ERROR
2022-11-11 16:01:15,053
Unhandled exception in listener callback
Traceback (most recent call last):
  File "c:\Users\alexa\Desktop\pro_110822\pro_110822_venv\lib\site-packages\pynput\_util\win32.py", line 386, in _handler
    converted = self._convert(code, msg, lpdata)
  File "c:\Users\alexa\Desktop\pro_110822\pro_110822_venv\lib\site-packages\pynput\_util\win32.py", line 401, in _convert
    raise NotImplementedError()
NotImplementedError

During handling of the above exception, another exception occurred:

Traceback (most recent call last):
  File "c:\Users\alexa\Desktop\pro_110822\pro_110822_venv\lib\site-packages\pynput\_util\__init__.py", line 228, in inner
    return f(self, *args, **kwargs)
  File "c:\Users\alexa\Desktop\pro_110822\pro_110822_venv\lib\site-packages\pynput\_util\win32.py", line 390, in _handler
    self._handle(code, msg, lpdata)
  File "c:\Users\alexa\Desktop\pro_110822\pro_110822_venv\lib\site-packages\pynput\mouse\_win32.py", line 208, in _handle
    self.on_move(data.pt.x, data.pt.y)
  File "c:\Users\alexa\Desktop\pro_110822\pro_110822_venv\lib\site-packages\pynput\_util\__init__.py", line 144, in inner
    if f(*args) is False:
  File "c:\Users\alexa\Desktop\pro_110822\pro_110822\sendmousemovement.py", line 27, in _on_move
    self.activeConnection.send()
AttributeError: 'int' object has no attribute 'send'
DEBUG
2022-11-11 16:01:33,163
Using proactor: IocpProactor
INFO
2022-11-11 16:01:37,232
 "c:\Users\alexa\Desktop\pro_110822\pro_110822\socketconnection.py"
(<class 'OSError'>, OSError(10049, 'The requested address is not valid in its context', None, 10049, None), <traceback object at 0x00000160ACFEE840>)
Traceback (most recent call last):
  File "c:\Users\alexa\Desktop\pro_110822\pro_110822\socketconnection.py", line 66, in connect_to_server
    self.s.connect((serverIP, port))
OSError: [WinError 10049] The requested address is not valid in its context

serverIP: 192.168.0.255
port: 12345
INFO
2022-11-11 16:01:39,254
 "c:\Users\alexa\Desktop\pro_110822\pro_110822\socketconnection.py"
(<class 'ConnectionRefusedError'>, ConnectionRefusedError(10061, 'No connection could be made because the target machine actively refused it', None, 10061, None), <traceback object at 0x00000160ACFEF080>)
Traceback (most recent call last):
  File "c:\Users\alexa\Desktop\pro_110822\pro_110822\socketconnection.py", line 66, in connect_to_server
    self.s.connect((serverIP, port))
ConnectionRefusedError: [WinError 10061] No connection could be made because the target machine actively refused it

serverIP: 192.168.0.1
port: 12345
INFO
2022-11-11 16:01:41,268
 "c:\Users\alexa\Desktop\pro_110822\pro_110822\socketconnection.py"
(<class 'ConnectionRefusedError'>, ConnectionRefusedError(10061, 'No connection could be made because the target machine actively refused it', None, 10061, None), <traceback object at 0x00000160ACFEE740>)
Traceback (most recent call last):
  File "c:\Users\alexa\Desktop\pro_110822\pro_110822\socketconnection.py", line 66, in connect_to_server
    self.s.connect((serverIP, port))
ConnectionRefusedError: [WinError 10061] No connection could be made because the target machine actively refused it

serverIP: 192.168.0.7
port: 12345
ERROR
2022-11-11 16:01:50,573
Unhandled exception in listener callback
Traceback (most recent call last):
  File "c:\Users\alexa\Desktop\pro_110822\pro_110822_venv\lib\site-packages\pynput\_util\__init__.py", line 228, in inner
    return f(self, *args, **kwargs)
  File "c:\Users\alexa\Desktop\pro_110822\pro_110822_venv\lib\site-packages\pynput\keyboard\_win32.py", line 287, in _process
    self.on_press(key)
  File "c:\Users\alexa\Desktop\pro_110822\pro_110822_venv\lib\site-packages\pynput\_util\__init__.py", line 144, in inner
    if f(*args) is False:
  File "c:\Users\alexa\Desktop\pro_110822\pro_110822\sendmousemovement.py", line 82, in _on_press
    self.activeConnection.send()
AttributeError: 'int' object has no attribute 'send'
